Workbook

Sheet Introduction

Sheet Présentation
A1: © Henri ISAAC, 2017
A2: Business plan e-commerce
A4: Ce classeur Excel est une proposition de business plan e-commerce.
A5: Il n'est pas complet ; il vous appartient de le compléter avec vos hypothèses.
A6: Il est construit sur un modèle d'affaires de vente directe en B2C.
A7: Seuls certains leviers marketing sont identifiés. Il vous appartient de les compléter en fonction de votre stratégie marketing.
A8: Étant donné l'importance de la maîtrise des coûts d'acquisition de clients en ligne, une feuille Excel y est entièrement consacrée.
A9: Vous pouvez ajouter ou modifier toutes les hypothèses.
A10: Il ne s'agit que d'un point de départ et d'autres feuilles peuvent s'ajouter en fonction de vos besoins.

Sheet Principales hypothèses
C1: Cte | E1: Année 1 | G1: Année 2 | I1: Année 3 | K1: Année 4 | M1: Année 5
A2: Principales hypothèses e-commerce
B3: Panier moyen première année | C3: 80
B4: Croissance annuelle du panier moyen | C4: 0.1
B5: Nombre de mois d'activité | E5: 12 | F5: 12 | G5: 12 | H5: 12 | I5: 12 | J5: 12 | K5: 12 | L5: 12 | M5: 12
B6: Taux de croissance visiteurs uniques/jour | C6: 0.8 | E6: 1000 | G6: =E6*(1+$C$6) -> 1800 | H6: =F6*(1+$C$6) -> 0 | I6: =G6*(1+$C$6) -> 3240 | J6: =H6*(1+$C$6) -> 0 | K6: =I6*(1+$C$6) -> 5832 | L6: =J6*(1+$C$6) -> 0 | M6: =K6*(1+$C$6) -> 10497.6
B7: Taux de conversion | E7: 0.005 | G7: 0.008 | I7: 0.01 | K7: 0.012 | M7: 0.015
A8: Achats (taux de marge brute)
B9: Prix d'achat des produits en % du prix de vente | C9: 0.4
A10: Frais e-commerce
B11: Frais de port moyen | C11: 5
A12: Marketing
B13: Budget Online Marketing | E13: 50000 | G13: 30000 | I13: 25000 | K13: 15000 | M13: 10000
B14: Performance Online Marketing (ratio) | E14: 2.5 | G14: 3 | I14: 3.5 | K14: 3.5 | M14: 3.5
B15: Base e-mail initiale | C15: 500
B16: Fréquence mensuelle des mailings | E16: 4 | G16: 5 | I16: 6 | K16: 6 | M16: 6
B17: Taux de conversion des e-mails | E17: 0.002 | F17: 0.002 | G17: 0.002 | H17: 0.002 | I17: 0.002 | J17: 0.002 | K17: 0.002 | L17: 0.002 | M17: 0.002
B18: Part des frais de port offerts (politique commerciale) | C18: 0.5
B19: Budget Communication
A20: Coûts opérationnels
A21: Développement de la plateforme technique e-commerce
B22: Analyse Conception | D22: 5000
B23: AMOA technique | D23: 15000
B24: Développement Front | D24: 30000
B25: Développement Back | D25: 15000
B26: Mises à jour du site
D27: =SUM(D22:D26) -> 65000 | G27: 6500 | I27: 6500 | K27: 15000 | M27: 10000
B28: Développement international
A29: Hébergement
B30: Hébergement annuel | E30: 5000 | F30: 5000 | G30: 5000 | H30: 5000 | I30: 5000 | J30: 5000 | K30: 5000 | L30: 5000 | M30: 5000
A31: SEM
B32: Pilotage de l'achat des mots clés | C32: 0.1
A33: e-Mailing
B34: Prix de l'e-mail au mille
B35: Prix d'une campagne d'e-mails
A36: Logistique
B37: Frais logistiques, hors transport, au colis | E37: 5 | F37: 1.2 | G37: 5 | H37: 1.2 | I37: 5 | J37: 1.2 | K37: 5 | L37: 1.2 | M37: 5
B38: Coût de la préparation de la commande | C38: 15 €/h chargée | D38: =15*35*48 -> 25200 | E38: =($D$38*'Les composantes du CA par canal'!C29)/'Les composantes du CA par canal'!C26 -> 1.8181818 | F38: =($D$38*'Les composantes du CA par canal'!D29)/'Les composantes du CA par canal'!D26 -> #DIV/0! | G38: =($D$38*'Les composantes du CA par canal'!E29)/'Les composantes du CA par canal'!E26 -> 1.8181818 | H38: =($D$38*'Les composantes du CA par canal'!F29)/'Les composantes du CA par canal'!F26 -> #DIV/0! | I38: =($D$38*'Les composantes du CA par canal'!G29)/'Les composantes du CA par canal'!G26 -> 1.8181818 | J38: =($D$38*'Les composantes du CA par canal'!H29)/'Les composantes du CA par canal'!H26 -> #DIV/0! | K38: =($D$38*'Les composantes du CA par canal'!I29)/'Les composantes du CA par canal'!I26 -> 1.8181818 | L38: =($D$38*'Les composantes du CA par canal'!J29)/'Les composantes du CA par canal'!J26 -> #DIV/0! | M38: =($D$38*'Les composantes du CA par canal'!K29)/'Les composantes du CA par canal'!K26 -> 1.8181818
B39: Coût total | E39: =SUM(E37:E38) -> 6.8181818 | F39: =SUM(F37:F38) -> #DIV/0! | G39: =SUM(G37:G38) -> 6.8181818 | H39: =SUM(H37:H38) -> #DIV/0! | I39: =SUM(I37:I38) -> 6.8181818 | J39: =SUM(J37:J38) -> #DIV/0! | K39: =SUM(K37:K38) -> 6.8181818 | L39: =SUM(L37:L38) -> #DIV/0! | M39: =SUM(M37:M38) -> 6.8181818
A40: Paiement en ligne
...

Sheet Les composantes du CA par canal
B1: T-x mois (Dév.) | C1: Année 1 | E1: Année 2 | G1: Année 3 | I1: Année 4 | K1: Année 5
A2: Panier moyen HT hors frais de port | C2: ='Principales hypothèses'!C3 -> 80 | E2: =C2*(1+'Principales hypothèses'!$C$4) -> 88 | G2: =E2*(1+'Principales hypothèses'!$C$4) -> 96.8 | I2: =G2*(1+'Principales hypothèses'!$C$4) -> 106.48 | K2: =I2*(1+'Principales hypothèses'!$C$4) -> 117.128
A4: Accès organique
A5: Visiteurs uniques annuels | C5: ='Principales hypothèses'!E6*'Principales hypothèses'!E5*30 -> 360000 | D5: ='Principales hypothèses'!F6*'Principales hypothèses'!F5*20 -> 0 | E5: ='Principales hypothèses'!G6*'Principales hypothèses'!G5*30 -> 648000 | F5: ='Principales hypothèses'!H6*'Principales hypothèses'!H5*30 -> 0 | G5: ='Principales hypothèses'!I6*'Principales hypothèses'!I5*30 -> 1166400 | H5: ='Principales hypothèses'!J6*'Principales hypothèses'!J5*30 -> 0 | I5: ='Principales hypothèses'!K6*'Principales hypothèses'!K5*30 -> 2099520 | K5: ='Principales hypothèses'!M6*'Principales hypothèses'!M5*30 -> 3779136
A6: Taux de conversion | C6: ='Principales hypothèses'!E7 -> 0.005 | D6: ='Principales hypothèses'!F7 | E6: ='Principales hypothèses'!G7 -> 0.008 | F6: ='Principales hypothèses'!H7 | G6: ='Principales hypothèses'!I7 -> 0.01 | H6: ='Principales hypothèses'!J7 | I6: ='Principales hypothèses'!K7 -> 0.012 | K6: ='Principales hypothèses'!M7 -> 0.015
A7: Nombre de transactions | C7: =C5*C6 -> 1800 | E7: =E5*E6 -> 5184 | G7: =G5*G6 -> 11664 | I7: =I5*I6 -> 25194.24 | K7: =K5*K6 -> 56687.04
A8: Chiffre d'affaires | C8: =C7*C2 -> 144000 | E8: =E7*E2 -> 456192 | G8: =G7*G2 -> 1129075.2 | I8: =I7*I2 -> 2682682.7 | K8: =K7*K2 -> 6639639.6
A10: Référencement payant (mots clés & affiliation)
A11: Budget | C11: 50000 | D11: ='Principales hypothèses'!F13 | E11: ='Principales hypothèses'!G13 -> 30000 | F11: ='Principales hypothèses'!H13 | G11: ='Principales hypothèses'!I13 -> 25000 | H11: ='Principales hypothèses'!J13 | I11: ='Principales hypothèses'!K13 -> 15000 | K11: ='Principales hypothèses'!M13 -> 10000
A12: Ratio | C12: ='Principales hypothèses'!E14 -> 2.5 | D12: ='Principales hypothèses'!F14 | E12: ='Principales hypothèses'!G14 -> 3 | F12: ='Principales hypothèses'!H14 | G12: ='Principales hypothèses'!I14 -> 3.5 | H12: ='Principales hypothèses'!J14 | I12: ='Principales hypothèses'!K14 -> 3.5 | K12: ='Principales hypothèses'!M14 -> 3.5
A13: Nombre de transactions | C13: =C14/C2 -> 1562.5 | E13: =E14/E2 -> 1022.7273 | G13: =G14/G2 -> 903.92562 | I13: =I14/I2 -> 493.05034 | K13: =K14/K2 -> 298.81839
A14: Chiffre d'affaires | C14: =C11*C12 -> 125000 | E14: =E11*E12 -> 90000 | G14: =G11*G12 -> 87500 | I14: =I11*I12 -> 52500 | K14: =K11*K12 -> 35000
A16: E-mailing
A17: Base e-mail | C17: ='Principales hypothèses'!C15 -> 500 | E17: =C17+(E13+E7)*0.5 -> 3603.3636 | G17: =E17+(G13+G7)*0.5 -> 9887.3264 | I17: =G17+(I13+I7)*0.5 -> 22730.972 | K17: =I17+(K13+K7)*0.5 -> 51223.901
A18: Fréquence d'envoi mensuelle | C18: ='Principales hypothèses'!E16 -> 4 | D18: ='Principales hypothèses'!F16 | E18: ='Principales hypothèses'!G16 -> 5 | F18: ='Principales hypothèses'!H16 | G18: ='Principales hypothèses'!I16 -> 6 | H18: ='Principales hypothèses'!J16 | I18: ='Principales hypothèses'!K16 -> 6 | K18: ='Principales hypothèses'!M16 -> 6
A19: Nombre d'e-mails envoyés | C19: =C18*'Principales hypothèses'!E5*C17 -> 24000 | E19: =E18*'Principales hypothèses'!G5*E17 -> 216201.82 | G19: =G18*'Principales hypothèses'!I5*G17 -> 711887.5 | I19: =I18*'Principales hypothèses'!K5*I17 -> 1636630 | K19: =K18*'Principales hypothèses'!M5*K17 -> 3688120.9
A20: Taux de conversion | C20: ='Principales hypothèses'!E17 -> 0.002 | D20: ='Principales hypothèses'!F17 -> 0.002 | E20: ='Principales hypothèses'!G17 -> 0.002 | F20: ='Principales hypothèses'!H17 -> 0.002 | G20: ='Principales hypothèses'!I17 -> 0.002 | H20: ='Principales hypothèses'!J17 -> 0.002 | I20: ='Principales hypothèses'!K17 -> 0.002 | K20: ='Principales hypothèses'!M17 -> 0.002
A21: Nombre de transactions | C21: =C19*C20 -> 48 | E21: =E19*E20 -> 432.40364 | G21: =G19*G20 -> 1423.775 | I21: =I19*I20 -> 3273.2599 | K21: =K19*K20 -> 7376.2417
A22: Chiffre d'affaires | C22: =C21*C2 -> 3840 | E22: =E21*E2 -> 38051.52 | G22: =G21*G2 -> 137821.42 | I22: =I21*I2 -> 348536.72 | K22: =K21*K2 -> 863964.44
A24: TOTAL
A25: Chiffre d'affaires total | C25: =C8+C14+C22 -> 272840 | E25: =E8+E14+E22 -> 584243.52 | G25: =G8+G14+G22 -> 1354396.6 | I25: =I8+I14+I22 -> 3083719.4 | K25: =K8+K14+K22 -> 7538604.1
A26: Nombre de transactions total | C26: =C21+C13+C7 -> 3410.5 | E26: =E21+E13+E7 -> 6639.1309 | G26: =G21+G13+G7 -> 13991.701 | I26: =I21+I13+I7 -> 28960.55 | K26: =K21+K13+K7 -> 64362.1
A27: Commandes journalières | C27: =C26/231 -> 14.764069 | E27: =E26/231 -> 28.740826 | G27: =G26/231 -> 60.570133 | I27: =I26/231 -> 125.37035 | K27: =K26/231 -> 278.62381
A28: Temps de préparation des commandes / jour | B28: 7 | C28: =C27*$B$28/60 -> 1.7224747 | E28: =E27*$B$28/60 -> 3.3530964 | G28: =G27*$B$28/60 -> 7.0665155 | I28: =I27*$B$28/60 -> 14.626541 | K28: =K27*$B$28/60 -> 32.506111
A29: ETP nécessaire pour préparer les commandes | C29: =C28/7 -> 0.24606782 | E29: =E28/7 -> 0.47901377 | G29: =G28/7 -> 1.0095022 | I29: =I28/7 -> 2.0895058 | K29: =K28/7 -> 4.6437302
A30: Répartition des revenus
A31: Organique | C31: =C8/C$25 -> 0.52778185 | D31: =D8/D$25 -> #DIV/0! | E31: =E8/E$25 -> 0.78082509 | F31: =F8/F$25 -> #DIV/0! | G31: =G8/G$25 -> 0.83363705 | H31: =H8/H$25 -> #DIV/0! | I31: =I8/I$25 -> 0.86995032 | J31: =J8/J$25 -> #DIV/0! | K31: =K8/K$25 -> 0.88075187
A32: Référencement payant | C32: =C14/C$25 -> 0.45814397 | D32: =D14/D$25 -> #DIV/0! | E32: =E14/E$25 -> 0.15404535 | F32: =F14/F$25 -> #DIV/0! | G32: =G14/G$25 -> 0.064604414 | H32: =H14/H$25 -> #DIV/0! | I32: =I14/I$25 -> 0.017024895 | J32: =J14/J$25 -> #DIV/0! | K32: =K14/K$25 -> 0.0046427694
A33: E-mailing | C33: =C22/C$25 -> 0.014074183 | D33: =D22/D$25 -> #DIV/0! | E33: =E22/E$25 -> 0.065129554 | F33: =F22/F$25 -> #DIV/0! | G33: =G22/G$25 -> 0.10175854 | H33: =H22/H$25 -> #DIV/0! | I33: =I22/I$25 -> 0.11302478 | J33: =J22/J$25 -> #DIV/0! | K33: =K22/K$25 -> 0.11460536
A35: Revenus
A36: Organique | C36: =C8 -> 144000 | D36: =D8 | E36: =E8 -> 456192 | F36: =F8 | G36: =G8 -> 1129075.2 | H36: =H8 | I36: =I8 -> 2682682.7 | J36: =J8 | K36: =K8 -> 6639639.6
A37: Référencement payant | C37: =C14 -> 125000 | D37: =D14 | E37: =E14 -> 90000 | F37: =F14 | G37: =G14 -> 87500 | H37: =H14 | I37: =I14 -> 52500 | J37: =J14 | K37: =K14 -> 35000
A38: E-mailing | C38: =C22 -> 3840 | D38: =D22 | E38: =E22 -> 38051.52 | F38: =F22 | G38: =G22 -> 137821.42 | H38: =H22 | I38: =I22 -> 348536.72 | J38: =J22 | K38: =K22 -> 863964.44

Sheet Profits & Loss (P&L)
B1: Dev | C1: A1 | D1: % CA | E1: A2 | F1: % CA | G1: A3 | H1: % CA | I1: A4 | J1: % CA | K1: A5 | L1: % CA
A2: Chiffre d'affaires total | C2: ='Les composantes du CA par canal'!C25 -> 272840 | D2: 1 | E2: ='Les composantes du CA par canal'!E25 -> 584243.52 | F2: 1 | G2: ='Les composantes du CA par canal'!G25 -> 1354396.6 | H2: 1 | I2: ='Les composantes du CA par canal'!I25 -> 3083719.4 | J2: 1 | K2: ='Les composantes du CA par canal'!K25 -> 7538604.1 | L2: 1
A4: Prix d'achat des produits | C4: =C2*(D4) -> 109136 | D4: ='Principales hypothèses'!$C$9 -> 0.4 | E4: =E2*(F4) -> 233697.41 | F4: ='Principales hypothèses'!$C$9 -> 0.4 | G4: =G2*(H4) -> 541758.65 | H4: ='Principales hypothèses'!$C$9 -> 0.4 | I4: =I2*(J4) -> 1233487.8 | J4: ='Principales hypothèses'!$C$9 -> 0.4 | K4: =K2*(L4) -> 3015441.6 | L4: ='Principales hypothèses'!$C$9 -> 0.4
A6: Marge brute | B6: =B2-B4 -> 0 | C6: =C2-C4 -> 163704 | D6: =C6/C2 -> 0.6 | E6: =E2-E4 -> 350546.11 | F6: =E6/E2 -> 0.6 | G6: =G2-G4 -> 812637.97 | H6: =G6/G2 -> 0.6 | I6: =I2-I4 -> 1850231.6 | J6: =I6/I2 -> 0.6 | K6: =K2-K4 -> 4523162.4 | L6: =K6/K2 -> 0.6
A8: Budget marketing
A9: Mots clés et affiliation | C9: ='Les composantes du CA par canal'!C11 -> 50000 | E9: ='Les composantes du CA par canal'!E11 -> 30000 | G9: ='Les composantes du CA par canal'!G11 -> 25000 | I9: ='Les composantes du CA par canal'!I11 -> 15000 | K9: ='Les composantes du CA par canal'!K11 -> 10000
A10: Frais de port offerts | C10: ='Les composantes du CA par canal'!C26*'Principales hypothèses'!$C$18*'Principales hypothèses'!$C$11 -> 8526.25 | E10: ='Les composantes du CA par canal'!E26*'Principales hypothèses'!$C$18*'Principales hypothèses'!$C$11 -> 16597.827 | G10: ='Les composantes du CA par canal'!G26*'Principales hypothèses'!$C$18*'Principales hypothèses'!$C$11 -> 34979.252 | I10: ='Les composantes du CA par canal'!I26*'Principales hypothèses'!$C$18*'Principales hypothèses'!$C$11 -> 72401.376 | K10: ='Les composantes du CA par canal'!K26*'Principales hypothèses'!$C$18*'Principales hypothèses'!$C$11 -> 160905.25
A11: Communication online (bannières, produits gratuits) | C11: ='Principales hypothèses'!E19 | E11: ='Principales hypothèses'!G19 | G11: ='Principales hypothèses'!I19 | I11: ='Principales hypothèses'!K19 | K11: ='Principales hypothèses'!M19
A12: Total budget marketing | C12: =SUM(C9:C11) -> 58526.25 | D12: =C12/C2 -> 0.21450759 | E12: =SUM(E9:E11) -> 46597.827 | F12: =E12/E2 -> 0.079757542 | G12: =SUM(G9:G11) -> 59979.252 | H12: =G12/G2 -> 0.04428485 | I12: =SUM(I9:I11) -> 87401.376 | J12: =I12/I2 -> 0.028342843 | K12: =SUM(K9:K11) -> 170905.25 | L12: =K12/K2 -> 0.022670676
A14: Marge commerciale | B14: =B6-B12 -> 0 | C14: =C6-C12 -> 105177.75 | D14: =C14/C2 -> 0.38549241 | E14: =E6-E12 -> 303948.28 | F14: =E14/E2 -> 0.52024246 | G14: =G6-G12 -> 752658.72 | H14: =G14/G2 -> 0.55571515 | I14: =I6-I12 -> 1762830.3 | J14: =I14/I2 -> 0.57165716 | K14: =K6-K12 -> 4352257.2 | L14: =K14/K2 -> 0.57732932
A16: Coûts e-commerce
A17: Développement et maintenance évolutive de la plateforme e-commerce | B17: ='Principales hypothèses'!D27 -> 65000 | C17: ='Principales hypothèses'!E27 | E17: ='Principales hypothèses'!G27 -> 6500 | G17: ='Principales hypothèses'!I27 -> 6500 | I17: ='Principales hypothèses'!K27 -> 15000 | K17: ='Principales hypothèses'!M27 -> 10000
A18: Développement international | C18: ='Principales hypothèses'!E28 | E18: ='Principales hypothèses'!G28 | G18: ='Principales hypothèses'!H28 | I18: ='Principales hypothèses'!I28 | K18: ='Principales hypothèses'!J28
A19: Amortissement Développement (sur 3 ans) | B19: =(B17+B18)*15/(3*12) -> 27083.333 | C19: =((B17+B18)*12/(3*12))+(C17+C18)/3 -> 21666.667 | D19: =C19/C$2 -> 0.079411621 | E19: =((B17+B18)*9/(3*12))+(C17+C18)/3+(E17+E18)/3 -> 18416.667 | F19: =E19/E$2 -> 0.031522244 | G19: =(C17+C18)/3+(E17+E18)/3+(G17+G18)/3 -> 4333.3333 | H19: =G19/G$2 -> 0.0031994567 | I19: =(E17+E18)/3+(G17+G18)/3+(I17+I18)/3 -> 9333.3333 | J19: =I19/I$2 -> 0.0030266481 | K19: =(G17+G18)/3+(I17+I18)/3+(K17+K18)/3 -> 10500 | L19: =K19/K$2 -> 0.0013928308
A20: Hébergement + bande passante | C20: ='Principales hypothèses'!E30*'Principales hypothèses'!E5/12 -> 5000 | D20: =C20/C$2 -> 0.018325759 | E20: ='Principales hypothèses'!G30*'Principales hypothèses'!G5/12 -> 5000 | F20: =E20/E$2 -> 0.0085580752 | G20: ='Principales hypothèses'!I30*'Principales hypothèses'!I5/12 -> 5000 | H20: =G20/G$2 -> 0.0036916808 | I20: ='Principales hypothèses'!K30*'Principales hypothèses'!K5/12 -> 5000 | J20: =I20/I$2 -> 0.0016214186 | K20: ='Principales hypothèses'!M30*'Principales hypothèses'!M5/12 -> 5000 | L20: =K20/K$2 -> 0.00066325277
A21: Pilotage des mots clés et affiliation (externalisé) | C21: =C9*'Principales hypothèses'!$C$32 -> 5000 | D21: =C21/C$2 -> 0.018325759 | E21: =E9*'Principales hypothèses'!$C$32 -> 3000 | F21: =E21/E$2 -> 0.0051348451 | G21: =G9*'Principales hypothèses'!$C$32 -> 2500 | H21: =G21/G$2 -> 0.0018458404 | I21: =I9*'Principales hypothèses'!$C$32 -> 1500 | J21: =I21/I$2 -> 0.00048642558 | K21: =K9*'Principales hypothèses'!$C$32 -> 1000 | L21: =K21/K$2 -> 0.00013265055
A22: Gestion des campagnes e-mails (externalisé) | C22: ='Les composantes du CA par canal'!C19*'Principales hypothèses'!$C$34/1000+'Les composantes du CA par canal'!C18*'Principales hypothèses'!E5*'Principales hypothèses'!$C$35 -> 0 | D22: =C22/C$2 -> 0 | E22: ='Les composantes du CA par canal'!E19*'Principales hypothèses'!$C$34/1000+'Les composantes du CA par canal'!E18*'Principales hypothèses'!G5*'Principales hypothèses'!$C$35 -> 0 | F22: =E22/E$2 -> 0 | G22: ='Les composantes du CA par canal'!G19*'Principales hypothèses'!$C$34/1000+'Les composantes du CA par canal'!G18*'Principales hypothèses'!I5*'Principales hypothèses'!$C$35 -> 0 | H22: =G22/G$2 -> 0 | I22: ='Les composantes du CA par canal'!I19*'Principales hypothèses'!$C$34/1000+'Les composantes du CA par canal'!I18*'Principales hypothèses'!K5*'Principales hypothèses'!$C$35 -> 0 | J22: =I22/I$2 -> 0 | K22: ='Les composantes du CA par canal'!K19*'Principales hypothèses'!$C$34/1000+'Les composantes du CA par canal'!K18*'Principales hypothèses'!M5*'Principales hypothèses'!$C$35 -> 0 | L22: =K22/K$2 -> 0
A23: Frais logistiques (interne) | C23: ='Les composantes du CA par canal'!C26*'Principales hypothèses'!E37 -> 17052.5 | D23: =C23/C$2 -> 0.0625 | E23: ='Les composantes du CA par canal'!E26*'Principales hypothèses'!G37 -> 33195.655 | F23: =E23/E$2 -> 0.056818182 | G23: ='Les composantes du CA par canal'!G26*'Principales hypothèses'!I37 -> 69958.503 | H23: =G23/G$2 -> 0.051652893 | I23: ='Les composantes du CA par canal'!I26*'Principales hypothèses'!K37 -> 144802.75 | J23: =I23/I$2 -> 0.046957175 | K23: ='Les composantes du CA par canal'!K26*'Principales hypothèses'!M37 -> 321810.5 | L23: =K23/K$2 -> 0.042688341
A24: Paiement en ligne | C24: ='Les composantes du CA par canal'!C25*'Principales hypothèses'!$C$41 -> 6821 | D24: =C24/C$2 -> 0.025 | E24: ='Les composantes du CA par canal'!E25*'Principales hypothèses'!$C$41 -> 14606.088 | F24: =E24/E$2 -> 0.025 | G24: ='Les composantes du CA par canal'!G25*'Principales hypothèses'!$C$41 -> 33859.916 | H24: =G24/G$2 -> 0.025 | I24: ='Les composantes du CA par canal'!I25*'Principales hypothèses'!$C$41 -> 77092.985 | J24: =I24/I$2 -> 0.025 | K24: ='Les composantes du CA par canal'!K25*'Principales hypothèses'!$C$41 -> 188465.1 | L24: =K24/K$2 -> 0.025
A25: Merchandising, mise à jour produits | B25: ='Principales hypothèses'!D57 -> 142500 | C25: ='Principales hypothèses'!E57 -> 61750 | D25: =C25/C$2 -> 0.22632312 | E25: ='Principales hypothèses'!G57 -> 66500 | F25: =E25/E$2 -> 0.1138224 | G25: ='Principales hypothèses'!I57 -> 71250 | H25: =G25/G$2 -> 0.052606451 | I25: ='Principales hypothèses'!K57 -> 76000 | J25: =I25/I$2 -> 0.024645563 | K25: ='Principales hypothèses'!M57 -> 80750 | L25: =K25/K$2 -> 0.010711532
A26: Relation client | C26: ='Les composantes du CA par canal'!C26*'Principales hypothèses'!E43*'Principales hypothèses'!$C$44 -> 1705.25 | D26: =C26/C$2 -> 0.00625 | E26: ='Les composantes du CA par canal'!E26*'Principales hypothèses'!G43*'Principales hypothèses'!$C$44 -> 3319.5655 | F26: =E26/E$2 -> 0.0056818182 | G26: ='Les composantes du CA par canal'!G26*'Principales hypothèses'!I43*'Principales hypothèses'!$C$44 -> 6995.8503 | H26: =G26/G$2 -> 0.0051652893 | I26: ='Les composantes du CA par canal'!I26*'Principales hypothèses'!K43*'Principales hypothèses'!$C$44 -> 14480.275 | J26: =I26/I$2 -> 0.0046957175 | K26: ='Les composantes du CA par canal'!K26*'Principales hypothèses'!M43*'Principales hypothèses'!$C$44 -> 32181.05 | L26: =K26/K$2 -> 0.0042688341
A27: SAV | C27: =C2*'Principales hypothèses'!E45 -> 10913.6 | D27: =C27/C$2 -> 0.04 | E27: =E2*'Principales hypothèses'!G45 -> 23369.741 | F27: =E27/E$2 -> 0.04 | G27: =G2*'Principales hypothèses'!I45 -> 54175.865 | H27: =G27/G$2 -> 0.04 | I27: =I2*'Principales hypothèses'!K45 -> 123348.78 | J27: =I27/I$2 -> 0.04 | K27: =K2*'Principales hypothèses'!M45 -> 301544.16 | L27: =K27/K$2 -> 0.04
A28: Pilotage (interne & externe) | C28: ='Principales hypothèses'!E48*'Principales hypothèses'!E47+'Principales hypothèses'!E49 -> 115000 | D28: =C28/C2 -> 0.42149245 | E28: ='Principales hypothèses'!G48*'Principales hypothèses'!G47+'Principales hypothèses'!G49 -> 22000 | F28: =E28/E2 -> 0.037655531 | G28: ='Principales hypothèses'!I48*'Principales hypothèses'!I47+'Principales hypothèses'!I49 -> 30000 | H28: =G28/G2 -> 0.022150085 | I28: ='Principales hypothèses'!K48*'Principales hypothèses'!K47+'Principales hypothèses'!K49 -> 60000 | J28: =I28/I2 -> 0.019457023 | K28: ='Principales hypothèses'!M48*'Principales hypothèses'!M47+'Principales hypothèses'!M49 -> 90000 | L28: =K28/K2 -> 0.01193855
A30: Total des charges | B30: =SUM(B19:B29) -> 169583.33 | C30: =SUM(C19:C29) -> 244909.02 | D30: =C30/C$2 -> 0.89762871 | E30: =SUM(E19:E29) -> 189407.72 | F30: =E30/E$2 -> 0.3241931 | G30: =SUM(G19:G29) -> 278073.47 | H30: =G30/G$2 -> 0.2053117 | I30: =SUM(I19:I29) -> 511558.12 | J30: =I30/I$2 -> 0.16588997 | K30: =SUM(K19:K29) -> 1031250.8 | L30: =K30/K$2 -> 0.13679599 | M30: =SUM(B30+C30+E30+G30+I30+K30) -> 2424782.5
A32: Marge nette | B32: =B14-B30 -> -169583.33 | C32: =C14-C30 -> -139731.27 | D32: =C32/C2 -> -0.51213629 | E32: =E14-E30 -> 114540.57 | F32: =E32/E2 -> 0.19604936 | G32: =G14-G30 -> 474585.25 | H32: =G32/G2 -> 0.35040345 | I32: =I14-I30 -> 1251272.1 | J32: =I32/I2 -> 0.40576719 | K32: =K14-K30 -> 3321006.4 | L32: =K32/K2 -> 0.44053333 | M32: =SUM(B32+C32+E32+G32+I32+K32) -> 4852089.7

Sheet Synthèse Marges
B1: T-x mois (Dév.) | C1: Année 1 | E1: Année 2 | G1: Année 3 | I1: Année 4 | K1: Année 5 | L1: % CA
A2: Chiffre d'affaires | B2: ='Les composantes du CA par canal'!B25 | C2: ='Les composantes du CA par canal'!C25 -> 272840 | E2: ='Les composantes du CA par canal'!E25 -> 584243.52 | G2: ='Les composantes du CA par canal'!G25 -> 1354396.6 | I2: ='Les composantes du CA par canal'!I25 -> 3083719.4 | K2: ='Les composantes du CA par canal'!K25 -> 7538604.1 | L2: 1
A3: Marge brute | B3: ='Profits & Loss (P&L)'!B6 -> 0 | C3: ='Profits & Loss (P&L)'!C6 -> 163704 | E3: ='Profits & Loss (P&L)'!E6 -> 350546.11 | G3: ='Profits & Loss (P&L)'!G6 -> 812637.97 | I3: ='Profits & Loss (P&L)'!I6 -> 1850231.6 | K3: ='Profits & Loss (P&L)'!K6 -> 4523162.4 | L3: =K3/#REF! -> #REF!
C4: =C3/C2 -> 0.6 | E4: =E3/E2 -> 0.6 | G4: =G3/G2 -> 0.6 | I4: =I3/I2 -> 0.6 | K4: =K3/K2 -> 0.6
A5: ='Profits & Loss (P&L)'!A14 -> Marge commerciale | B5: ='Profits & Loss (P&L)'!B14 -> 0 | C5: ='Profits & Loss (P&L)'!C14 -> 105177.75 | E5: ='Profits & Loss (P&L)'!E14 -> 303948.28 | G5: ='Profits & Loss (P&L)'!G14 -> 752658.72 | I5: ='Profits & Loss (P&L)'!I14 -> 1762830.3 | K5: ='Profits & Loss (P&L)'!K14 -> 4352257.2
C6: =C5/C2 -> 0.38549241 | E6: =E5/E2 -> 0.52024246 | G6: =G5/G2 -> 0.55571515 | I6: =I5/I2 -> 0.57165716 | K6: =K5/K2 -> 0.57732932
A7: ='Profits & Loss (P&L)'!A32 -> Marge nette | B7: ='Profits & Loss (P&L)'!B32 -> -169583.33 | C7: ='Profits & Loss (P&L)'!C32 -> -139731.27 | E7: ='Profits & Loss (P&L)'!E32 -> 114540.57 | G7: ='Profits & Loss (P&L)'!G32 -> 474585.25 | I7: ='Profits & Loss (P&L)'!I32 -> 1251272.1 | K7: ='Profits & Loss (P&L)'!K32 -> 3321006.4
C8: =C7/C2 -> -0.51213629 | E8: =E7/E2 -> 0.19604936 | G8: =G7/G2 -> 0.35040345 | I8: =I7/I2 -> 0.40576719 | K8: =K7/K2 -> 0.44053333
